Workbook
Name Category: #REF!
Name Category: #REF!
Name Category: #REF!
Name Category: Lookup!$S$2:$S$6
Name M_1: 'CREW EXPIRY DATES'!#REF!
Name M_1: Template!#REF!
Name M_1: 'Template -Matrix Archive'!$G$42
Name M_1: #REF!
Name M_2: 'CREW EXPIRY DATES'!#REF!
Name M_2: Template!#REF!
Name M_2: 'Template -Matrix Archive'!$G$44
Name M_2: #REF!
Name M_3: 'CREW EXPIRY DATES'!#REF!
Name M_3: Template!#REF!
Name M_3: 'Template -Matrix Archive'!$G$46
Name M_3: #REF!
Name M_4: 'CREW EXPIRY DATES'!#REF!
Name M_4: Template!#REF!
Name M_4: 'Template -Matrix Archive'!$G$48
Name M_4: #REF!
Name M_5: 'CREW EXPIRY DATES'!#REF!
Name M_5: Template!#REF!
Name M_5: 'Template -Matrix Archive'!$G$50
Name M_5: #REF!
Name M_6: 'CREW EXPIRY DATES'!#REF!
Name M_6: Template!#REF!
Name M_6: 'Template -Matrix Archive'!$G$52
Name M_6: #REF!
Name M_7: 'CREW EXPIRY DATES'!#REF!
Name M_7: Template!#REF!
Name M_7: 'Template -Matrix Archive'!$G$54
Name M_7: #REF!
Name Name: #REF!
Name Name: #REF!
Name Name: #REF!
Name Name: #REF!
Name Name: Lookup!$I$2:$I$249
Name NameList: OFFSET(#REF!,MATCH(#REF!,#REF!,0)-1,0,COUNTIF(#REF!,#REF!),1)
Name NameList: OFFSET(#REF!,MATCH(#REF!,#REF!,0)-1,0,COUNTIF(#REF!,#REF!),1)
Name NameList: OFFSET(#REF!,MATCH(#REF!,#REF!,0)-1,0,COUNTIF(#REF!,#REF!),1)
Name NameList: OFFSET( Lookup!$I$2, MATCH(INDIRECT("Master!$H"&ROW()), Lookup!$K$2:$K$504, 0)-1, 0, COUNTIF(Lookup!$K$2:$K$504, INDIRECT("Master!$H"&ROW())), 1 )
Name NameListMatrix: OFFSET(#REF!, MATCH(#REF!,#REF!, 0)-1, 0, COUNTIF(#REF!,#REF!), 1)
Name NameListMatrix: OFFSET(#REF!, MATCH(#REF!,#REF!, 0)-1, 0, COUNTIF(#REF!,#REF!), 1)
Name NameListMatrix: OFFSET(#REF!, MATCH(#REF!,#REF!, 0)-1, 0, COUNTIF(#REF!,#REF!), 1)
Name NameListMatrix: OFFSET(Lookup!$I$2, MATCH('Template - Matrix'!$B$5, Lookup!$K:$K, 0)-1, 0, COUNTIF(Lookup!$K:$K, 'Template - Matrix'!$B$5), 1)
Name PartnershipList: #REF!
Name PartnershipList: #REF!
Name PartnershipList: #REF!
Name PartnershipList: Lookup!$G$2:$G$6
Name Position: #REF!
Name Position: #REF!
Name Position: #REF!
Name Position: #REF!
Name PositionList: #REF!
Name PositionList: #REF!
Name PositionList: #REF!
Name PositionList: Lookup!$C$2:$C$9
Name Reference: #REF!
Name Reference: #REF!
Name Reference: #REF!

Sheet Instruction Sheet
A1: Spreadsheet Tab Overview:
A2: Instruction Sheet | B2: Overview of the process and guidance on field input requirements
A3: Master | B3: Master sheet to be used for requests
A4: Template Matrix | B4: Sheet to be used for providing Crew Change compliance matrix
A5: Crew Change Dates | B5: info page containing crew change dates
A6: Position Reference | B6: info page containing position reference guidance
A7: ID# Convention | B7: info page on naming convention to use when creating ID # on Master tab column A "ID #"
A8: Instructions
A10: Master:
A11: On tab Master work from left to right starting in column B 'Status'. Use the legend below to check which fields you need to fill out.
A13: Legend for Master tab
B14: Person entering exemption/query to input
B15: Portways Input Field
B16: MRL Input Field
B17: Calculated field -do not input
B18: Field not required - do not input
A20: Master Tab Column Information
A21: Column | B21: Field Type | C21: Field Input | D21: Description
A22: ID# | B22: Free Text | C22: see tab naming convention | D22: Create ID for request based on naming convention guidance
A23: Status | B23: Dropdown | C23: Open - PW | D23: Item open awaiting action from PW
A24: Status | B24: Dropdown | C24: Open - MRL | D24: Item open awaiting action from MRL
A25: Status | B25: Dropdown | C25: Closed - PW | D25: Item closed by MRL
A26: Status | B26: Dropdown | C26: Closed - MRL | D26: Item closed by PW
A27: Type | B27: Dropdown | C27: Exemption Request - PW | D27: Exemption requested by PW
A28: Type | B28: Dropdown | C28: Exemption Request - MRL Query | D28: Exemption requested by PW following an MRL Query
A29: Type | B29: Dropdown | C29: MRL Query | D29: Query submitted by MRL for PW Action
A30: Type | B30: Dropdown | C30: PW Query | D30: Query submitted by PW for MRL info only
A31: Date Exemption Requested | B31: Date Input | D31: Enter the date you submit the exemption request via email notification
A32: Date Query PW | B32: Date Input | D32: Enter the date you submit the query via email notification
A33: Date Query MRL | B33: Date Input | D33: Enter the date you submit the query via email notification
A34: Closeout Date | B34: Date Input | D34: Enter the date the action is closed out via email notification
A35: Partnership | B35: Dropdown | D35: Select the relevant partnership from the dropdown
A36: Vessel | B36: Calculated column | D36: Automatic field based on partnership inputted in previous cell
A37: Name | B37: Dropdown | D37: Select the relevant name from the dropdown
A38: Sam # | B38: Calculated column | D38: Automatic field based on name inputted in previous cell
A39: Position | B39: Dropdown | D39: Select the relevant MRL Operational Manning position from the dropdown
A40: Position Reference | B40: Dropdown - dependent | C40: see tab position reference | D40: Select the relevant MRL Operational Manning position reference number from the dropdown. This field will restrict based on the position selected in previous position column. See tab Position Reference for overview of position reference assignments by position
A41: Shift | B41: Calculated column | C41: see tab position reference | D41: Automatic field based on the position reference entered
A42: Training Matrix Title | B42: Dropdown | D42: Select the relevant Training Matrix item from the dropdown
A43: Effective From | B43: Date Input | D43: Enter the date you request the exemption to start from
...

Sheet Template -Matrix Archive
A2: Partnership | C2: < Start Here
A3: Crew Change
A4: Crew Change From
A5: Crew Change To
G10: Legend:
G11: M | H11: Mandatory
G12: Mˣ | H12: Mandatory if applicable — see notes below
G13: R | H13: Recommended
H14: Not Required
A16: Position Reference | B16: Position | C16: Shift | D16: Name | E16: Sam # | F16: From Date | G16: To Date | H16: Comments | I16: 1. Qualification | AC16: 2. Vessel Specific | AG16: 3. Project Specific | AI16: 4. Master Specific | AP16: 5. Cargo System | AT16: 6. High Risk Work Licence (HRWL) | AV16: 7. Permit to Work | AY16: 8. Vessel Induction | BA16: 9. Project Induction
I17: QL-01 | J17: QL-02 | K17: QL-03 | L17: QL-04 | M17: QL-05 | N17: QL-06 | O17: QL-07 | P17: QL-08 | Q17: QL-09 | R17: QL-10 | S17: QL-11 | T17: QL-12 | U17: QL-13 | V17: QL-14 | W17: QL-15 | X17: QL-16 | Y17: QL-17 | Z17: QL-18 | AA17: QL-19 | AB17: QL-20 | AC17: VS-01 | AD17: VS-02 | AE17: VS-04 | AF17: VS-05 | AG17: PS-01 | AH17: PS-02 | AI17: MS-01 | AJ17: MS-02 | AK17: MS-03 | AL17: MS-04 | AM17: MS-05 | AN17: MS-06 | AO17: MS-07 | AP17: CS-01 | AQ17: CS-02 | AR17: CS-03 | AS17: CS-04 | AT17: HR-01 | AU17: HR-02 | AV17: PT-01 | AW17: PT-02 | AX17: PT-03 | AY17: VI-01 | AZ17: VI-02 | BA17: PI-01 | BB17: PI-02 | BC17: PI-03 | BD17: PI-04 | BE17: PI-05 | BF17: PI-06 | BG17: PI-07 | BH17: PI-08 | BI17: PI-09 | BJ17: PI-10
I18: Master | J18: Chief Mate | K18: Master <100m NC | L18: Master <45m NC | M18: Engineer Class 1, Chief Engineer (Motor) | N18: Engineer Class 2, Second Engineer, Chief Engineer <3000 kW (Motor) | O18: Engineer Class 3 NC | P18: Master <24m NC | Q18: Marine Engine Driver Grade 2 NC | R18: Integrated Rating, Able Seafarer - Deck, Able Seafarer - Engineer (STCW Reg II/5 & III/5) | S18: Marine Cook | T18: Certificate of Safety Training (COST) | U18: ECDIS - STCW Reg II/1 & II/2 | V18: GMDSS - STCW Reg IV/2 | W18: Long Range Operator Certificate of Proficiency (LROCP) | X18: Fast Rescue Craft (FRC) | Y18: AMSA Certificate of Medical Fitness - Form 303 | Z18: Provide First Aid - HLTAID011 | AA18: Adv Resuscitation and Oxygen Therapy - HLTIAD015 | AB18: Use hygienic practices for food safety - SITXFSA005 | AC18: Maritime Security Identification Card | AD18: ECDIS Type Specific - Furuno ECDIS, FMD series | AE18: Helm CONNECT - Crew Basic + Jobs | AF18: MRN - Connecting Tug to Barge Articouple System | AG18: MRN - Marine Fauna Observer | AH18: MinRes - Mooring Operations Awareness - Onslow | AI18: Phase 1 - ASD and ATB Theory & Assessment | AJ18: Phase 2 - Simulator Training & Practical Assessment ASD | AK18: Phase 3 - Simulator Training & Practical Assessment ATB | AL18: Phase 4a - On-Water Training & Practical Assessment ASD | AM18: Phase 4b - On-Water Training & Practical Assessment ATB | AN18: Phase 5 - On-Water Passing in the LNG Swing Basin | AO18: Pilbara Ports Port of Ashburton Pilotage Exemption Certificate | AP18: MRN - EMS Tech Material Handling Systems - Single Point Loading System | AQ18: MRN - EMS Tech Material Handling Systems - Self-Unloading System | AR18: Cargo System - Operator - Practical | AS18: Cargo System - Trainer - Practical | AT18: HRWL - Dogging - Dogging (DG) | AU18: HRWL - Vehicle loading crane (CV) | AV18: MinRes - Lock Holder, Isolation and Tagging | AW18: Enter and Work in Confined Spaces - RIIWHS202E | AX18: Work Safely at Heights - RIIWHS204E | AY18: Onboard induction, familiarisation and training - Tug and Barge | AZ18: MRN - Tug and Barge Induction | BA18: MinRes - Code of Conduct & Business Integrity | BB18: MinRes - Corporate Safety Induction | BC18: MinRes - Hazard Report Card, Take Time & JHA | BD18: MinRes - Manual Handling | BE18: MinRes - Operational Health and Safety Induction | BF18: MinRes - Safe and Respectful Behaviours | BG18: MinRes - Welcome to MinRes | BH18: MinRes - Cybersecurity Awareness Training | BI18: MinRes - Critical Risk Management (CRM) Awareness | BJ18: MinRes - Airborne Contaminant Awareness Training
A19: 1 | B19: Master | C19: Shift 1 | F19: =IF(ISBLANK($B$4), "", $B$7) | G19: =IF(ISBLANK($B$4), "", $B$5) | I19: M | U19: M | V19: M | X19: M³ | Y19: M | Z19: M | AA19: M⁴ | AC19: M | AD19: M | AE19: M | AF19: M | AG19: M | AH19: M | AI19: M | AJ19: M | AK19: M | AL19: M | AM19: M | AN19: M | AO19: M | AP19: M | AQ19: M | AR19: M | AV19: M | AW19: M | AX19: M | AY19: M | AZ19: M | BA19: M | BB19: M | BC19: M | BD19: M | BE19: M | BF19: M | BG19: M | BH19: M | BI19: M | BJ19: M
A20: 2 | B20: Master | C20: Shift 2 | F20: =IF(ISBLANK($B$4), "", $B$7) | G20: =IF(ISBLANK($B$4), "", $B$5) | I20: M | U20: M | V20: M | X20: M³ | Y20: M | Z20: M | AA20: M⁴ | AC20: M | AD20: M | AE20: M | AF20: M | AG20: M | AH20: M | AI20: M | AJ20: M | AK20: M | AL20: M | AM20: M | AN20: M | AO20: M | AP20: M | AQ20: M | AR20: M | AV20: M | AW20: M | AX20: M | AY20: M | AZ20: M | BA20: M | BB20: M | BC20: M | BD20: M | BE20: M | BF20: M | BG20: M | BH20: M | BI20: M | BJ20: M
A21: 3 | B21: Chief Officer | C21: Shift 1 | F21: =IF(ISBLANK($B$4), "", $B$7) | G21: =IF(ISBLANK($B$4), "", $B$5) | J21: M | U21: M | V21: M | X21: M³ | Y21: M | Z21: M | AA21: M⁴ | AC21: M | AD21: M | AE21: M | AF21: M | AG21: M | AH21: M | AI21: R | AJ21: R | AK21: R | AL21: R | AM21: R | AN21: M | AO21: R | AP21: M | AQ21: M | AR21: M | AS21: M | AT21: R | AU21: M⁶ | AV21: M | AY21: M | AZ21: M | BA21: M | BB21: M | BC21: M | BD21: M | BE21: M | BF21: M | BG21: M | BH21: M | BI21: M | BJ21: M
A22: 4 | B22: Chief Officer | C22: Shift 2 | F22: =IF(ISBLANK($B$4), "", $B$7) | G22: =IF(ISBLANK($B$4), "", $B$5) | K22: M | T22: M | U22: M | V22: M | W22: M | X22: M³ | Y22: M | Z22: M | AA22: M⁴ | AC22: M | AD22: M | AE22: M | AF22: M | AG22: M | AH22: M | AI22: R | AJ22: R | AK22: R | AL22: R | AM22: R | AN22: M | AO22: R | AP22: M | AQ22: M | AR22: M | AS22: M | AT22: R | AU22: M⁶ | AV22: M | AY22: M | AZ22: M | BA22: M | BB22: M | BC22: M | BD22: M | BE22: M | BF22: M | BG22: M | BH22: M | BI22: M | BJ22: M
A23: 5 | B23: Second Mate | C23: Shift 1 | F23: =IF(ISBLANK($B$4), "", $B$7) | G23: =IF(ISBLANK($B$4), "", $B$5) | L23: M | T23: M | U23: M | W23: M | X23: M³ | Y23: M | Z23: M | AA23: M⁴ | AC23: M | AD23: M | AE23: M | AF23: M | AG23: M | AH23: M | AP23: M | AQ23: M | AR23: M | AT23: R | AU23: M⁶ | AV23: M | AY23: M | AZ23: M | BA23: M | BB23: M | BC23: M | BD23: M | BE23: M | BF23: M | BG23: M | BH23: M | BI23: M | BJ23: M
A24: 6 | B24: Second Mate | C24: Shift 2 | F24: =IF(ISBLANK($B$4), "", $B$7) | G24: =IF(ISBLANK($B$4), "", $B$5) | L24: M | T24: M | U24: M | W24: M | X24: M³ | Y24: M | Z24: M | AA24: M⁴ | AC24: M | AD24: M | AE24: M | AF24: M | AG24: M | AH24: M | AP24: M | AQ24: M | AR24: M | AT24: R | AU24: M⁶ | AV24: M | AY24: M | AZ24: M | BA24: M | BB24: M | BC24: M | BD24: M | BE24: M | BF24: M | BG24: M | BH24: M | BI24: M | BJ24: M
A25: 7 | B25: Chief Engineer | C25: Shift 1 | F25: =IF(ISBLANK($B$4), "", $B$7) | G25: =IF(ISBLANK($B$4), "", $B$5) | M25: M | X25: M³ | Y25: M | Z25: M | AA25: M⁴ | AC25: M | AE25: M | AH25: M | AP25: M | AQ25: M | AR25: R | AV25: M | AW25: M | AX25: M | AY25: M | AZ25: M | BA25: M | BB25: M | BC25: M | BD25: M | BE25: M | BF25: M | BG25: M | BH25: M | BI25: M | BJ25: M
A26: 8 | B26: First Engineer | C26: Shift 2 | F26: =IF(ISBLANK($B$4), "", $B$7) | G26: =IF(ISBLANK($B$4), "", $B$5) | N26: M | X26: M³ | Y26: M | Z26: M | AA26: M⁴ | AC26: M | AE26: M | AH26: M | AP26: M | AQ26: M | AR26: R | AV26: M | AW26: M | AX26: M | AY26: M | AZ26: M | BA26: M | BB26: M | BC26: M | BD26: M | BE26: M | BF26: M | BG26: M | BH26: M | BI26: M | BJ26: M
A27: 9 | B27: Assistant Engineer | C27: Shift 1 | F27: =IF(ISBLANK($B$4), "", $B$7) | G27: =IF(ISBLANK($B$4), "", $B$5) | O27: M | T27: M | X27: M³ | Y27: M | Z27: M | AA27: M⁴ | AC27: M | AE27: M | AH27: M | AP27: M | AQ27: M | AT27: M | AU27: M⁶ | AV27: M | AX27: M | AY27: M | AZ27: M | BA27: M | BB27: M | BC27: M | BD27: M | BE27: M | BF27: M | BG27: M | BH27: M | BI27: M | BJ27: M
A28: 10 | B28: Assistant Engineer | C28: Shift 2 | F28: =IF(ISBLANK($B$4), "", $B$7) | G28: =IF(ISBLANK($B$4), "", $B$5) | O28: M | T28: M | X28: M³ | Y28: M | Z28: M | AA28: M⁴ | AC28: M | AE28: M | AH28: M | AP28: M | AQ28: M | AT28: M | AU28: M⁶ | AV28: M | AX28: M | AY28: M | AZ28: M | BA28: M | BB28: M | BC28: M | BD28: M | BE28: M | BF28: M | BG28: M | BH28: M | BI28: M | BJ28: M
A29: 11 | B29: GPH | C29: Shift 1 | F29: =IF(ISBLANK($B$4), "", $B$7) | G29: =IF(ISBLANK($B$4), "", $B$5) | P29: M¹ | Q29: M¹ | R29: M¹ | T29: M² | X29: M³ | Y29: M | Z29: M | AA29: M⁴ | AB29: M⁵ | AC29: M | AE29: M | AH29: M | AP29: M | AQ29: M | AT29: M | AU29: M⁶ | AV29: M | AX29: M⁷ | AY29: M | AZ29: M | BA29: M | BB29: M | BC29: M | BD29: M | BE29: M | BF29: M | BG29: M | BH29: M | BI29: M | BJ29: M
A30: 12 | B30: GPH | C30: Shift 2 | F30: =IF(ISBLANK($B$4), "", $B$7) | G30: =IF(ISBLANK($B$4), "", $B$5) | P30: M¹ | Q30: M¹ | R30: M¹ | T30: M² | X30: M³ | Y30: M | Z30: M | AA30: M⁴ | AB30: M⁵ | AC30: M | AE30: M | AH30: M | AP30: M | AQ30: M | AT30: M | AU30: M⁶ | AV30: M | AX30: M⁷ | AY30: M | AZ30: M | BA30: M | BB30: M | BC30: M | BD30: M | BE30: M | BF30: M | BG30: M | BH30: M | BI30: M | BJ30: M
A31: 13 | B31: GPH | C31: Shift 1 | F31: =IF(ISBLANK($B$4), "", $B$7) | G31: =IF(ISBLANK($B$4), "", $B$5) | P31: M¹ | Q31: M¹ | R31: M¹ | T31: M² | X31: M³ | Y31: M | Z31: M | AA31: M⁴ | AB31: M⁵ | AC31: M | AE31: M | AH31: M | AP31: M | AQ31: M | AT31: M | AU31: M⁶ | AV31: M | AX31: M⁷ | AY31: M | AZ31: M | BA31: M | BB31: M | BC31: M | BD31: M | BE31: M | BF31: M | BG31: M | BH31: M | BI31: M | BJ31: M
A32: 14 | B32: GPH | C32: Shift 2 | F32: =IF(ISBLANK($B$4), "", $B$7) | G32: =IF(ISBLANK($B$4), "", $B$5) | P32: M¹ | Q32: M¹ | R32: M¹ | T32: M² | X32: M³ | Y32: M | Z32: M | AA32: M⁴ | AB32: M⁵ | AC32: M | AE32: M | AH32: M | AP32: M | AQ32: M | AT32: M | AU32: M⁶ | AV32: M | AX32: M⁷ | AY32: M | AZ32: M | BA32: M | BB32: M | BC32: M | BD32: M | BE32: M | BF32: M | BG32: M | BH32: M | BI32: M | BJ32: M
A33: 15 | B33: GPH | C33: Shift 1 | F33: =IF(ISBLANK($B$4), "", $B$7) | G33: =IF(ISBLANK($B$4), "", $B$5) | P33: M¹ | Q33: M¹ | R33: M¹ | T33: M² | X33: M³ | Y33: M | Z33: M | AA33: M⁴ | AB33: M⁵ | AC33: M | AE33: M | AH33: M | AP33: M | AQ33: M | AT33: M | AU33: M⁶ | AV33: M | AX33: M⁷ | AY33: M | AZ33: M | BA33: M | BB33: M | BC33: M | BD33: M | BE33: M | BF33: M | BG33: M | BH33: M | BI33: M | BJ33: M
A34: 16 | B34: GPH | C34: Shift 2 | F34: =IF(ISBLANK($B$4), "", $B$7) | G34: =IF(ISBLANK($B$4), "", $B$5) | P34: M¹ | Q34: M¹ | R34: M¹ | T34: M² | X34: M³ | Y34: M | Z34: M | AA34: M⁴ | AB34: M⁵ | AC34: M | AE34: M | AH34: M | AP34: M | AQ34: M | AT34: M | AU34: M⁶ | AV34: M | AX34: M⁷ | AY34: M | AZ34: M | BA34: M | BB34: M | BC34: M | BD34: M | BE34: M | BF34: M | BG34: M | BH34: M | BI34: M | BJ34: M
A35: 15 | B35: Assistant Engineer | C35: Shift 1 | F35: =IF(ISBLANK($B$4), "", $B$7) | G35: =IF(ISBLANK($B$4), "", $B$5) | O35: M | T35: M | X35: M³ | Y35: M | Z35: M | AA35: M⁴ | AC35: M | AE35: M | AH35: M | AP35: M | AQ35: M | AT35: M | AU35: M⁶ | AV35: M | AX35: M | AY35: M | AZ35: M | BA35: M | BB35: M | BC35: M | BD35: M | BE35: M | BF35: M | BG35: M | BH35: M | BI35: M | BJ35: M
A36: 16 | B36: Assistant Engineer | C36: Shift 2 | F36: =IF(ISBLANK($B$4), "", $B$7) | G36: =IF(ISBLANK($B$4), "", $B$5) | O36: M | T36: M | X36: M³ | Y36: M | Z36: M | AA36: M⁴ | AC36: M | AE36: M | AH36: M | AP36: M | AQ36: M | AT36: M | AU36: M⁶ | AV36: M | AX36: M | AY36: M | AZ36: M | BA36: M | BB36: M | BC36: M | BD36: M | BE36: M | BF36: M | BG36: M | BH36: M | BI36: M | BJ36: M
A37: 17 | B37: Cook | C37: N/A | F37: =IF(ISBLANK($B$4), "", $B$7) | G37: =IF(ISBLANK($B$4), "", $B$5) | S37: M | T37: M | X37: M³ | Y37: M | Z37: M | AA37: M⁴ | AC37: M | AV37: M | AY37: M | AZ37: M | BA37: M | BB37: M | BC37: M | BD37: M | BE37: M | BF37: M | BG37: M | BH37: M | BI37: M | BJ37: M
G39: Notes:
G41: Mandatory if applicable | H41: Training Matrix Item | J41: Required Number of Position to Hold Requirement | K41: Shift 1 | L41: Shift 2
G42: M¹ | H42: QL-08 Master <24m NC QL-09 Marine Engine Driver Grade 2 NC QL-10 Integrated Rating, Able Seafarer - Deck, Able Seafarer Engineer (STCW Reg II/5 & III/5) | J42: Number Required | K42: All must hold at least one of the listed Certificates of Proficiency or Certificates of Competency
J43: Position | K43: GPH
G44: M² | H44: QL-12 Certificate of Safety Training (COST) | J44: Number Required | K44: Required if GPH holds Master <24 NC or Marine Engine Driver Grade 2 NC. All non STCW CoC/CoR must have COST.
J45: Position | K45: GPH
G46: M³ | H46: QL-16 Fast Rescue Craft (FRC) | J46: Number Required | K46: 4
J47: Position | K47: Any Position
G48: M⁴ | H48: QL-19 Adv Resuscitation and Oxygen Therapy - HLTIAD015 | J48: Number Required | K48: 2 | L48: 2
...

Sheet Lookup
A1: TMItem | B1: Shift | C1: PositionList | D1: Position | E1: Reference | F1: Shift | G1: PartnershipList | H1: Vessel | I1: Name | J1: SAM # | K1: Partnership | M1: ID # | N1: Partnership | O1: From | P1: To | R1: Type | S1: Category | T1: Status
A2: Master | B2: Shift 1 | C2: Master | D2: Master | E2: 1 | F2: Shift 1 | G2: Norse Marine PTY LTD | H2: Airlie/Odin | M2: CC01 | N2: Norse Marine PTY LTD | O2: 45597 | P2: 45624 | R2: Exemption Request - PW | S2: Info Required | T2: Open - PW
A3: Chief Mate | B3: Shift 2 | C3: Chief Officer | D3: Master | E3: 2 | F3: Shift 2 | G3: Sindri | H3: Montebello/Balder | M3: CC02 | N3: Norse Marine PTY LTD | O3: 45625 | P3: 45652 | R3: Exemption Request - MRL Query | S3: Admin Action | T3: Open - MRL
A4: Master <100m NC | C4: Second Mate | D4: Chief Officer | E4: 3 | F4: Shift 1 | G4: Optima Marine Pty Ltd | H4: Rosily/Bessie | M4: CC03 | N4: Norse Marine PTY LTD | O4: 45653 | P4: 45680 | R4: Exemption Request - UNI | S4: Not Required | T4: Open UNI
A5: Master <45m NC | C5: Chief Engineer | D5: Chief Officer | E5: 4 | F5: Shift 2 | G5: United Marine Pty Ltd | H5: Coolibah/Thor | M5: CC04 | N5: Norse Marine PTY LTD | O5: 45681 | P5: 45708 | R5: MRL Query | S5: Approved | T5: Complete before joining
A6: Engineer Class 1, Chief Engineer (Motor) | C6: First Engineer | D6: Second Mate | E6: 5 | F6: Shift 1 | G6: ShipMates Maritime Group Pty Ltd | H6: Peak/Vidar | M6: CC05 | N6: Norse Marine PTY LTD | O6: 45709 | P6: 45736 | R6: PW Query | S6: Not Approved | T6: Closed UNI
A7: Engineer Class 2, Second Engineer <3000kW (Motor) | C7: Assistant Engineer | D7: Second Mate | E7: 6 | F7: Shift 2 | M7: CC06 | N7: Norse Marine PTY LTD | O7: 45737 | P7: 45764 | R7: Close before joining | T7: Closed - PW
A8: Engineer Class 3 NC | C8: GPH | D8: Chief Engineer | E8: 7 | F8: Shift 1 | M8: CC07 | N8: Norse Marine PTY LTD | O8: 45765 | P8: 45792 | T8: Closed - MRL
A9: Master <24m NC | C9: Cook | D9: First Engineer | E9: 8 | F9: Shift 2 | M9: CC08 | N9: Norse Marine PTY LTD | O9: 45793 | P9: 45820
A10: Marine Engine Driver Grade 2 NC | D10: Assistant Engineer | E10: 9 | F10: Shift 1 | M10: CC09 | N10: Norse Marine PTY LTD | O10: 45821 | P10: 45848
A11: Integrated Rating, Able Seafarer - Deck, Able Seafarer Engine | D11: Assistant Engineer | E11: 10 | F11: Shift 2 | M11: CC10 | N11: Norse Marine PTY LTD | O11: 45849 | P11: 45876
A12: Marine Cook | D12: Assistant Engineer | E12: 15 | F12: Shift 1 | M12: CC11 | N12: Norse Marine PTY LTD | O12: 45877 | P12: 45904
A13: Certificate of Safety Training (COST) | D13: Assistant Engineer | E13: 16 | F13: Shift 2 | M13: CC12 | N13: Norse Marine PTY LTD | O13: 45905 | P13: 45932
A14: ECDIS—STCW Reg II/1 & II/2 | D14: GPH | E14: 11 | F14: Shift 1 | M14: CC13 | N14: Norse Marine PTY LTD | O14: 45933 | P14: 45960
A15: ECDIS Type Specific - Furuno ECDIS, FMD series | D15: GPH | E15: 12 | F15: Shift 2 | M15: CC14 | N15: Norse Marine PTY LTD | O15: 45961 | P15: 45988
A16: GMDSS—STCW Reg IV/2 | D16: GPH | E16: 13 | F16: Shift 1 | M16: CC15 | N16: Norse Marine PTY LTD | O16: 45989 | P16: 46019
A17: Proficiency in fast rescue boats—STCW Regulation VI/2 Code A -VI/2 table A-VI/2-2 | D17: GPH | E17: 14 | F17: Shift 2 | M17: CC16 | N17: Norse Marine PTY LTD | O17: 46020 | P17: 46042
A18: AMSA Certificate of Medical Fitness - Form 303 | D18: GPH | E18: 15 | F18: Shift 1 | M18: CC17 | N18: Norse Marine PTY LTD | O18: 46043 | P18: 46070
A19: Provide First Aid - HLTAID011 | D19: GPH | E19: 16 | F19: Shift 2 | M19: CC18 | N19: Norse Marine PTY LTD | O19: 46071 | P19: 46098
A20: Adv Resuscitation and Oxygen Therapy - HLTIAD015 | D20: Cook | E20: 17 | F20: N/A | M20: CC19 | N20: Norse Marine PTY LTD | O20: 46099 | P20: 46126
A21: Use hygienic practices for food safety - SITXFSA005 | M21: CC20 | N21: Norse Marine PTY LTD | O21: 46127 | P21: 46154
A22: Maritime Security Identification Card | M22: CC21 | N22: Norse Marine PTY LTD | O22: 46155 | P22: 46182
A23: Theory and user training in DUKC® Series 5 | M23: CC22 | N23: Norse Marine PTY LTD | O23: 46183 | P23: 46210
A24: Helm Crew - Basic & Crew Jobs | M24: CC23 | N24: Norse Marine PTY LTD | O24: 46211 | P24: 46238
A25: MRN - Connecting Tug to Barge Articouple System | M25: CC24 | N25: Norse Marine PTY LTD | O25: 46239 | P25: 46266
A26: LMS - MinRes - Mooring Operations Awareness - Onslow | M26: CC25 | N26: Norse Marine PTY LTD | O26: 46267 | P26: 46294
A27: MRN - Effective Use of Tugs for Pilot Exempt Masters | M27: CC26 | N27: Norse Marine PTY LTD | O27: 46295 | P27: 46322
A28: MRN - Good Practice Guideline for Pilots | M28: CC27 | N28: Norse Marine PTY LTD | O28: 46323 | P28: 46350
A29: ASD TUG HANDLING (TugSim) | M29: CC28 | N29: Norse Marine PTY LTD | O29: 46351 | P29: 46378
A30: ARTICULATED TUG & BARGE (ATB) MANOEUVRING & PEC (TugSim) | M30: CC29 | N30: Norse Marine PTY LTD | O30: 46379 | P30: 46406
A31: ASD/ATB MANOEUVRING, PORT OPERATIONS AND PEC TRAINING – Onboard | M31: CC30 | N31: Norse Marine PTY LTD | O31: 46407 | P31: 45729
A32: Passing in the LNG Swing Basin - Simulator | M32: CC06 | N32: Optima Marine Pty Ltd | O32: 45730 | P32: 45757
... A60: DO NOT USE 02/26 - Rigging | M60: CC13 | N60: ShipMates Maritime Group Pty Ltd | O60: 45919 | P60: 45946
M61: CC14 | N61: ShipMates Maritime Group Pty Ltd | O61: 45947 | P61: 45974
M62: CC15 | N62: ShipMates Maritime Group Pty Ltd | O62: 45975 | P62: 46002
M63: CC16 | N63: ShipMates Maritime Group Pty Ltd | O63: 46003 | P63: 46035
M64: CC17 | N64: ShipMates Maritime Group Pty Ltd | O64: 46036 | P64: 46063
M65: CC18 | N65: ShipMates Maritime Group Pty Ltd | O65: 46064 | P65: 46091
M66: CC19 | N66: ShipMates Maritime Group Pty Ltd | O66: 46092 | P66: 46119
M67: CC20 | N67: ShipMates Maritime Group Pty Ltd | O67: 46120 | P67: 46147
...

Sheet CREW EXPIRY DATES
E6: Legend:
E7: M | F7: Mandatory
E8: Mˣ | F8: Mandatory if applicable — see notes below
E9: R | F9: Recommended
F10: Not Required
A12: Position Reference | B12: Name | C12: Position | D12: Sam # | E12: 1. Qualification | Z12: 2. Vessel Specific | AD12: 3. Project Specific | AF12: 4. Master Specific | AM12: 5. Cargo System | AQ12: 6. High Risk Work Licence (HRWL) | AS12: 7. Permit to Work | AV12: 8. Vessel Induction | AX12: 9. Project Induction
E14: QL-01 | F14: QL-02 | G14: QL-03 | H14: QL-04 | I14: QL-05 | J14: QL-06 | K14: QL-07 | L14: QL-08 | M14: QL-09 | N14: QL-10 | O14: QL-11 | P14: QL-12 | Q14: QL-13 | R14: QL-14 | S14: QL-15 | T14: QL-16 | U14: QL-17 | V14: QL-18 | W14: QL-19 | X14: QL-20 | Z14: VS-01 | AA14: VS-02 | AB14: VS-04 | AC14: VS-05 | AD14: PS-01 | AE14: PS-02 | AF14: MS-01 | AG14: MS-02 | AH14: MS-03 | AI14: MS-04 | AJ14: MS-05 | AK14: MS-06 | AL14: MS-07 | AM14: CS-01 | AN14: CS-02 | AO14: CS-03 | AP14: CS-04 | AQ14: HR-01 | AR14: HR-02 | AS14: PT-01 | AT14: PT-02 | AU14: PT-03 | AV14: VI-01 | AW14: VI-02 | AX14: PI-01 | AY14: PI-02 | AZ14: PI-03 | BA14: PI-04 | BB14: PI-05 | BC14: PI-06 | BD14: PI-07 | BE14: PI-08 | BF14: PI-09 | BG14: PI-10
E15: Master | F15: Chief Mate | G15: Master <100m NC | H15: Master <45m NC | I15: Engineer Class 1, Chief Engineer (Motor) | J15: Engineer Class 2, Second Engineer, Chief Engineer <3000 kW (Motor) | K15: Engineer Class 3 NC | L15: Master <24m NC | M15: Marine Engine Driver Grade 2 NC | N15: Integrated Rating, Able Seafarer - Deck, Able Seafarer - Engineer (STCW Reg II/5 & III/5) | O15: Marine Cook | P15: Certificate of Safety Training (COST) | Q15: ECDIS - STCW Reg II/1 & II/2 | R15: GMDSS - STCW Reg IV/2 | S15: Long Range Operator Certificate of Proficiency (LROCP) | T15: Fast Rescue Craft (FRC) | U15: AMSA Certificate of Medical Fitness - Form 303 | V15: Provide First Aid - HLTAID011 | W15: Adv Resuscitation and Oxygen Therapy - HLTIAD015 | X15: Use hygienic practices for food safety - SITXFSA005 | Y15: Advanced Fire Fighting | Z15: Maritime Security Identification Card | AA15: ECDIS Type Specific - Furuno ECDIS, FMD series | AB15: Helm CONNECT - Crew Basic + Jobs | AC15: MRN - Connecting Tug to Barge Articouple System | AD15: MRN - Marine Fauna Observer | AE15: MinRes - Mooring Operations Awareness - Onslow | AF15: Phase 1 - ASD and ATB Theory & Assessment | AG15: Phase 2 - Simulator Training & Practical Assessment ASD | AH15: Phase 3 - Simulator Training & Practical Assessment ATB | AI15: Phase 4a - On-Water Training & Practical Assessment ASD | AJ15: Phase 4b - On-Water Training & Practical Assessment ATB | AK15: Phase 5 - On-Water Passing in the LNG Swing Basin | AL15: Pilbara Ports Port of Ashburton Pilotage Exemption Certificate | AM15: MRN - EMS Tech Material Handling Systems - Single Point Loading System | AN15: MRN - EMS Tech Material Handling Systems - Self-Unloading System | AO15: Cargo System - Operator - Practical | AP15: Cargo System - Trainer - Practical | AQ15: HRWL - Dogging - Dogging (DG) | AR15: HRWL - Vehicle loading crane (CV) | AS15: MinRes - Lock Holder, Isolation and Tagging | AT15: Enter and Work in Confined Spaces - RIIWHS202E | AU15: Work Safely at Heights - RIIWHS204E | AV15: Onboard induction, familiarisation and training - Tug and Barge | AW15: MRN - Tug and Barge Induction | AX15: MinRes - Code of Conduct & Business Integrity | AY15: MinRes - Corporate Safety Induction | AZ15: MinRes - Hazard Report Card, Take Time & JHA | BA15: MinRes - Manual Handling | BB15: MinRes - Operational Health and Safety Induction | BC15: MinRes - Safe and Respectful Behaviours | BD15: MinRes - Welcome to MinRes | BE15: MinRes - Cybersecurity Awareness Training | BF15: MinRes - Critical Risk Management (CRM) Awareness | BG15: MinRes - Airborne Contaminant Awareness Training
B16: EVANS, Brenton | C16: Master | D16: e91754E | E16: 47994 | Q16: 47994 | R16: 47398 | T16: 47287 | U16: 46785 | V16: 46811 | Z16: 46419 | AA16: Y | AB16: Y | AC16: 46758 | AD16: 46757 | AE16: 46722 | AF16: Y | AG16: Y | AH16: Y | AI16: Y | AJ16: Y | AK16: Y | AL16: 46487 | AM16: 46666 | AN16: 46644 | AO16: Y | AS16: 47521 | AT16: 46860 | AU16: 46860 | AV16: Y | AW16: 46464 | AX16: 46755 | AY16: 46424 | AZ16: 47521 | BA16: 46789 | BB16: 46308 | BC16: 46755 | BD16: Y | BE16: 46714 | BF16: 46755 | BG16: 46392
B17: TYMOFEYEV, Arthur | C17: Master | D17: t83382T | E17: 46656 | Q17: 46656 | R17: N | T17: 46274 | U17: 46586 | V17: 46554 | Z17: 47515 | AA17: Y | AB17: Y | AC17: 46771 | AD17: 46768 | AE17: 46713 | AF17: Y | AG17: Y | AH17: Y | AI17: Y | AJ17: Y | AK17: Y | AL17: 46964 | AM17: 46715 | AN17: 46715 | AO17: Y | AS17: 47250 | AT17: 46676 | AU17: 46676 | AV17: Y | AW17: 46478 | AX17: 46811 | AY17: 46811 | AZ17: 47249 | BA17: 46518 | BB17: 46308 | BC17: 46811 | BD17: Y | BE17: 46756 | BF17: 46756 | BG17: 46772
B18: KUMAR, Preetham | C18: Master | D18: k83381K | E18: 46837 | Q18: ? | R18: 46650 | T18: ? | U18: 46619 | V18: 46185 | Z18: 47270 | AA18: Y | AB18: Y | AC18: 46743 | AD18: 46743 | AE18: 46733 | AF18: Y | AG18: Y | AH18: Y | AI18: Y | AJ18: Y | AK18: Y | AL18: 46199 | AM18: 46721 | AN18: 46721 | AO18: Y | AQ18: 46988 | AS18: 47251 | AT18: 46667 | AU18: 46667 | AV18: Y | AW18: 46731 | AX18: 46721 | AY18: 46888 | AZ18: 47251 | BA18: 46520 | BB18: 46260 | BC18: 46721 | BD18: Y | BE18: 46721 | BF18: 46783 | BG18: 46743
B19: JONES, Matthew James | C19: Master | D19: j83385J | E19: 46387 | Q19: 47869 | R19: 46432 | T19: 46308 | U19: 46305 | V19: 46166 | Z19: 47453 | AA19: Y | AB19: Y | AC19: 46770 | AD19: 46766 | AE19: 46729 | AF19: Y | AG19: Y | AH19: Y | AI19: Y | AJ19: Y | AK19: Y | AL19: 46268 | AM19: 46729 | AN19: 46729 | AO19: Y | AS19: 47249 | AT19: 46779 | AU19: 46779 | AV19: Y | AW19: 46525 | AX19: 46852 | AY19: 46851 | AZ19: 47249 | BA19: 46518 | BB19: 47325 | BC19: 46778 | BD19: Y | BE19: 46729 | BF19: 46769 | BG19: 46769
B20: FARMER, Evan | C20: Master | D20: f86373F | E20: 46861 | Q20: 46861 | R20: 47460 | U20: 46339 | V20: 46583 | Z20: 47270 | AA20: Y | AB20: Y | AC20: 46744 | AD20: 46742 | AE20: 46728 | AF20: Y | AG20: Y | AH20: Y | AI20: Y | AJ20: Y | AK20: Y | AL20: 46284 | AM20: 46627 | AN20: 46626 | AO20: Y | AS20: 47299 | AT20: 46729 | AU20: 46667 | AV20: Y | AW20: 46454 | AX20: 46630 | AY20: 46895 | AZ20: 47300 | BA20: 46567 | BB20: 47318 | BC20: 46873 | BD20: Y | BE20: 46769 | BF20: 46873 | BG20: 46742
B21: WITHARANA, Ruwan | C21: Chief Officer - Unlimited | D21: w83384W | E21: 46326 | Q21: ? | R21: 46326 | T21: 47185 | U21: 46673 | V21: 46403 | Y21: 46440 | Z21: 47088 | AA21: Y | AB21: Y | AC21: 46770 | AD21: 46764 | AE21: 46713 | AF21: Y | AK21: Y | AM21: 46649 | AN21: 46647 | AO21: Y | AP21: Y | AS21: 47221 | AV21: Y | AW21: 46484 | AX21: 46778 | AY21: 46778 | AZ21: 47221 | BA21: 46492 | BB21: 46308 | BC21: 46778 | BD21: Y | BE21: 46769 | BF21: 46772 | BG21: 46769
B22: JITENDER, Rohin | C22: Chief Officer - Unlimited | D22: j84281J | E22: 47869 | Q22: 47869 | R22: 47877 | T22: 47408 | U22: 46823 | V22: 46510 | W22: 46513 | Z22: 47088 | AA22: Y | AB22: Y | AC22: 46743 | AD22: 46743 | AE22: 46743 | AF22: Y | AG22: Y | AH22: Y | AI22: Y | AJ22: Y | AK22: Y | AL22: N | AM22: 46685 | AN22: 46685 | AO22: Y | AP22: Y | AS22: 47246 | AV22: Y | AW22: 46493 | AX22: 46873 | AY22: 46862 | AZ22: 47246 | BA22: 46515 | BB22: 47326 | BC22: 46843 | BD22: Y | BE22: 46727 | BF22: 46769 | BG22: 46770
B23: STEWART, Ryan | C23: Chief Officer - 100m | D23: s84589S | G23: 47768 | P23: 48068 | Q23: 47967 | R23: 47775 | T23: 46242 | U23: 46438 | V23: 46444 | W23: 46437 | Y23: 47967 | Z23: 47058 | AA23: Y | AB23: Y | AC23: 46780 | AD23: 46743 | AE23: 46721 | AK23: Y | AM23: 46677 | AN23: 46677 | AO23: Y | AP23: Y | AS23: 47248 | AV23: Y | AW23: 46453 | AX23: 46824 | AY23: 46824 | AZ23: 47248 | BA23: 46517 | BB23: 47325 | BC23: 46826 | BD23: Y | BE23: 46730 | BF23: 46678 | BG23: 46730
B24: ROGERS, Michael | C24: Chief Officer - 100m | D24: r83383R | G24: 47754 | P24: 47966 | Q24: 47966 | R24: 47345 | T24: 47965 | U24: 46410 | V24: 46402 | W24: 46088 | Z24: 47300 | AA24: Y | AB24: Y | AC24: 46768 | AD24: 46756 | AE24: 46591 | AK24: Y | AM24: 46666 | AN24: 46666 | AO24: Y | AP24: Y | AS24: 47224 | AV24: Y | AW24: 46475 | AX24: 46773 | AY24: 46986 | AZ24: 47224 | BA24: 46493 | BB24: 47314 | BC24: 46666 | BD24: Y | BE24: 46720 | BF24: 46757 | BG24: 47031
B25: RUBOCK, Zachary | C25: Second Mate | D25: r84283R | H25: 46522 | M25: 46379 | P25: 46387 | Q25: 47209 | R25: 46650 | U25: 46535 | V25: 46501 | Z25: 46661 | AA25: Y | AB25: Y | AC25: 46733 | AD25: 46740 | AE25: 46721 | AM25: 46721 | AN25: 46680 | AO25: Y | AQ25: 46638 | AR25: 46638 | AS25: 47247 | AT25: 46760 | AU25: 46761 | AV25: Y | AW25: 46453 | AX25: 46802 | AY25: 46842 | AZ25: 47244 | BA25: 46513 | BB25: 47314 | BC25: 46802 | BD25: Y | BE25: 46721 | BF25: 46559 | BG25: 46742
B26: AYERS, Christopher James | C26: Second Mate | D26: a90100A | H26: 47321 | P26: 46739 | Q26: 47877 | R26: 47383 | U26: 46788 | V26: 46344 | X26: Y | Z26: 47484 | AA26: Y | AB26: Y | AC26: 46745 | AD26: 46740 | AE26: 46731 | AM26: 46633 | AN26: 46633 | AO26: Y | AQ26: 47359 | AR26: 47359 | AS26: 47433 | AV26: Y | AW26: 46745 | AX26: 46731 | AY26: 46731 | AZ26: 47433 | BA26: 46702 | BB26: 46308 | BC26: 46731 | BD26: Y | BE26: 46743 | BF26: 46786 | BG26: 46745
B27: COOK, Jack | C27: Second Mate | D27: c84297C | G27: 48042 | H27: 47929 | P27: 47386 | Q27: 47883 | R27: 47054 | U27: 46757 | V27: 46953 | W27: 46085 | Z27: 46905 | AA27: Y | AB27: Y | AC27: 46740 | AD27: 46742 | AE27: 46721 | AF27: Y | AG27: Y | AM27: 46722 | AN27: 46721 | AO27: Y | AQ27: 48023 | AS27: 47247 | AV27: Y | AW27: 46740 | AX27: 46806 | AY27: 46515 | AZ27: 47246 | BA27: 46516 | BB27: 47315 | BC27: 46806 | BD27: Y | BE27: 46723 | BF27: 47110 | BG27: 46743
B28: KINGDON, Matthew | C28: Second Mate | D28: k84420K | H28: 47096 | M28: 47550 | P28: 46973 | Q28: 47209 | R28: 47344 | U28: 46856 | V28: 46985 | Y28: 47787 | Z28: 46631 | AA28: Y | AB28: Y | AC28: 46756 | AD28: 46756 | AE28: 46714 | AM28: 46665 | AN28: 46665 | AO28: Y | AQ28: 46565 | AR28: 46565 | AS28: 47246 | AV28: Y | AW28: 46460 | AX28: 46769 | AY28: 46853 | AZ28: 46515 | BA28: 46515 | BB28: 46308 | BC28: 46769 | BD28: Y | BE28: 46714 | BF28: 46769 | BG28: 46756
B29: BAUTISTA, John Leo | C29: Second Mate | D29: b91092B | H29: 47296 | P29: 47296 | Q29: ? | R29: 47296 | U29: 46465 | V29: 46759 | Z29: 47392 | AA29: Y | AB29: Y | AC29: 46769 | AD29: 46766 | AE29: 46716 | AM29: 46652 | AN29: 46651 | AO29: Y | AS29: 47488 | AV29: Y | AW29: 46474 | AX29: 46769 | AY29: 46392 | AZ29: 47488 | BA29: 46757 | BB29: 46308 | BC29: 46769 | BD29: Y | BE29: 46770 | BF29: 46770 | BG29: 46769
B30: OZHOGA, Andriy | C30: Chief Engineer | D30: k84420K | I30: 47051 | U30: 46596 | V30: 46433 | Z30: 46447 | AB30: Y | AC30: 46743 | AE30: 46728 | AM30: 46721 | AN30: 46626 | AO30: N | AS30: 47246 | AT30: 46808 | AU30: 46808 | AV30: Y | AW30: 46457 | AX30: 46728 | AY30: 46851 | AZ30: 47246 | BA30: 46516 | BB30: 47317 | BC30: 46728 | BD30: Y | BE30: 46728 | BF30: 46768 | BG30: 46744
B31: PATWARDHAN, Anand | C31: Chief Engineer | D31: p84418P | I31: 47453 | U31: 46731 | V31: 46769 | Z31: 46753 | AB31: Y | AC31: 46756 | AE31: 46717 | AM31: 46643 | AN31: 46649 | AO31: N | AS31: 47246 | AT31: 46677 | AU31: 46677 | AV31: Y | AW31: 46722 | AX31: 46769 | AY31: 46821 | AZ31: 46881 | BA31: 46515 | BB31: 46308 | BC31: 46769 | BD31: Y | BE31: 46717 | BF31: 46643 | BG31: 46756
B32: BUTLER, David Robert | C32: First Engineer | D32: b92561B | J32: 47247 | U32: 46660 | V32: 46440 | Z32: 46692 | AB32: Y | AC32: 46744 | AE32: 46726 | AM32: 46627 | AN32: 46627 | AO32: N | AS32: 47580 | AT32: 46331 | AU32: 46330 | AV32: Y | AW32: 46727 | AX32: 46813 | AY32: 46484 | AZ32: 47580 | BA32: 46848 | BB32: 47318 | BC32: 46843 | BD32: Y | BE32: 46726 | BF32: 46484 | BG32: 46744
B33: ATHIHE, Savio | C33: First Engineer | D33: a84346A | J33: 46855 | U33: 46955 | V33: 46471 | Y33: 46933 | Z33: 47574 | AB33: Y | AC33: 46769 | AE33: 46721 | AM33: 46658 | AN33: 46658 | AO33: N | AS33: 47248 | AT33: 46719 | AU33: 46719 | AV33: Y | AW33: 46486 | AX33: 46851 | AY33: 46866 | AZ33: 47247 | BA33: 47247 | BB33: 46192 | BC33: 46851 | BD33: Y | BE33: 46723 | BF33: 46768 | BG33: 46770
B34: KEELEY, Finn | C34: Assistant Engineer | D34: k88211K | K34: 47343 | U34: 46701 | V34: 46731 | Z34: 47392 | AB34: Y | AE34: 46744 | AM34: 46635 | AN34: 46635 | AQ34: 47378 | AR34: 47378 | AS34: 47357 | AU34: 46859 | AV34: Y | AW34: 46453 | AX34: 46731 | AY34: 46261 | AZ34: 47355 | BA34: 46624 | BB34: 47317 | BC34: 46731 | BD34: Y | BE34: 46731 | BF34: 46769 | BG34: 46744
B35: MILLER, Jamie | C35: Assistant Engineer | D35: m84414M | K35: 47102 | P35: 46349 | U35: 46623 | V35: 47169 | W35: 46438 | Z35: 47574 | AB35: Y | AE35: 46730 | AM35: 46731 | AN35: 46731 | AQ35: 47268 | AS35: 47250 | AU35: N | AV35: Y | AW35: 46457 | AX35: 46855 | AY35: 46854 | AZ35: 47613 | BA35: 46519 | BB35: 47331 | BC35: 46855 | BD35: Y | BE35: 46771 | BF35: 46771 | BG35: 46784
B36: TADIAMAN, Mark Jay | C36: Assistant Engineer | D36: t84295T | M36: 47838 | N36: 47246 | P36: 47245 | U36: 46821 | V36: 46485 | Z36: 47543 | AB36: Y | AE36: 46727 | AM36: 46638 | AN36: 46630 | AQ36: 47912 | AS36: 47247 | AU36: N | AV36: Y | AW36: 46455 | AX36: 46753 | AY36: 46804 | AZ36: 47247 | BA36: 46516 | BB36: 47317 | BC36: 46783 | BD36: Y | BE36: 46727 | BF36: 46771 | BG36: 46771
B37: MATA, Marlou | C37: Assistant Engineer | D37: m62159M | M37: 47530 | N37: 46606 | P37: 46606 | U37: 46788 | V37: 46993 | Z37: 47058 | AB37: Y | AE37: 46719 | AM37: 46651 | AN37: 46651 | AQ37: 47296 | AR37: 46934 | AS37: 47231 | AU37: N | AV37: y | AW37: 46723 | AX37: 46793 | AY37: 46794 | AZ37: 47230 | BA37: 46500 | BB37: 46308 | BC37: 46793 | BD37: y | BE37: 46769 | BF37: 46769 | BG37: 46769
B38: BATERNA, Eric | C38: Assistant Engineer | D38: b93089B | M38: 47831 | P38: 47770 | U38: 46660 | V38: 46854 | Z38: 46753 | AB38: Y | AE38: 46730 | AM38: 46641 | AN38: 46641 | AQ38: 47596 | AR38: 47596 | AS38: 47584 | AT38: 46834 | AU38: 46837 | AV38: Y | AW38: 46730 | AX38: 46483 | AY38: 46483 | AZ38: 47583 | BA38: 46853 | BB38: 47332 | BC38: 46852 | BD38: Y | BE38: 46783 | BF38: 46753 | BG38: 46783
B39: CLEMONES, Leon | C39: Assistant Engineer | D39: c91093C | K39: 47696 | P39: 47834 | U39: 46876 | V39: 46949 | Z39: 46388 | AB39: Y | AE39: 46719 | AM39: 46665 | AN39: 46658 | AQ39: 47956 | AR39: 47956 | AS39: 47495 | AT39: 46731 | AU39: 46963 | AV39: Y | AW39: 46769 | AX39: 46769 | AY39: 46399 | AZ39: 47495 | BA39: 46764 | BB39: 47313 | BC39: 46769 | BD39: Y | BE39: 46717 | BF39: 46769 | BG39: 46769
B40: PEJIC, Anton | C40: Assistant Engineer | D40: p85920P | K40: 46609 | P40: 47268 | U40: 46640 | V40: 46763 | Z40: 47300 | AB40: Y | AE40: 46717 | AM40: 46643 | AN40: 46643 | AQ40: 46819 | AR40: 46819 | AS40: 47285 | AU40: N | AV40: Y | AW40: 46458 | AX40: 46922 | AY40: 46891 | AZ40: 47284 | BA40: 46554 | BB40: 46308 | BC40: 46770 | BD40: Y | BE40: 46718 | BF40: 46643 | BG40: 46768
B41: WRIGHT, Andrew | C41: Assistant Engineer | D41: w90518W | K41: 47744 | P41: 47233 | U41: 46326 | V41: 46662 | Z41: 46784 | AB41: Y | AE41: 46789 | AM41: 46792 | AN41: 47233 | AQ41: 47394 | AR41: 47394 | AS41: 47454 | AU41: N | AV41: Y | AW41: 46789 | AX41: 46787 | AY41: 46357 | AZ41: 47454 | BA41: 47153 | BB41: 46308 | BC41: 46787 | BD41: Y | BE41: 46789 | BF41: 46787 | BG41: 46789
B42: KEOGH, Cornelius James | C42: Assistant Engineer | D42: k97556K | J42: 47408 | U42: 46858 | V42: 46866 | Z42: 46600 | AB42: Y | AE42: 46722 | AM42: 46708 | AN42: 46708 | AQ42: 47541 | AS42: 47810 | AT42: 46536 | AU42: 46883 | AV42: Y | AW42: 46888 | AX42: 46708 | AY42: 46708 | AZ42: 47810 | BA42: 47079 | BB42: 46308 | BC42: 46708 | BD42: Y | BE42: 46772 | BF42: 46708 | BG42: 46772
B43: MURUGESAN, Karthik | C43: Assistant Engineer | D43: m90534M | M43: 47701 | P43: 47513 | U43: 46344 | V43: 46710 | Z43: 46327 | AB43: Y | AE43: 46717 | AM43: 46717 | AN43: 46717 | AQ43: 48001 | AS43: 47462 | AU43: N | AV43: Y | AW43: 46721 | AX43: 46768 | AY43: 46365 | AZ43: 47462 | BA43: 46731 | BB43: 46308 | BC43: 46768 | BD43: Y | BE43: 46769 | BF43: 46768 | BG43: 46403
B44: MACDONALD, Justin | C44: GPH | D44: m99351M | H44: 47750 | N44: 47939 | P44: 47487 | T44: 47947 | U44: 46729 | V44: 46808 | W44: 46361 | X44: N | Z44: 46692 | AB44: Y | AE44: 46796 | AM44: 46794 | AN44: 46794 | AQ44: 47860 | AR44: 47860 | AS44: 47889 | AU44: N | AV44: Y | AW44: 46796 | AX44: 46792 | AY44: 46792 | AZ44: 47889 | BA44: 47158 | BB44: 47314 | BC44: 46792 | BD44: Y | BE44: 46796 | BF44: 46793 | BG44: 46795
B45: MICHALZIC, Travis | C45: GPH | D45: m94475M | H45: 47981 | M45: 47406 | P45: 46590 | Q45: 48015 | R45: 46552 | U45: 46590 | V45: 47300 | X45: N | Z45: 46874 | AB45: N | AE45: 46732 | AM45: 46732 | AN45: 46732 | AQ45: 47443 | AS45: 47661 | AU45: N | AV45: Y | AW45: 46732 | AX45: 46564 | AY45: 46564 | AZ45: 47663 | BA45: 46932 | BB45: 46308 | BC45: 46567 | BD45: Y | BE45: 46732 | BF45: 46564 | BG45: 46774
B46: EVANS, Dylan | C46: GPH | D46: e84287E | H46: 47693 | M46: 47787 | N46: 47729 | U46: 46828 | V46: 47238 | W46: 46507 | X46: Y | Z46: 47484 | AB46: Y | AE46: 46727 | AM46: 46636 | AN46: 46636 | AQ46: 47202 | AR46: 47202 | AS46: 47246 | AU46: N | AV46: Y | AW46: 46448 | AX46: 46514 | AY46: 46515 | AZ46: 47246 | BA46: 46515 | BB46: 47315 | BC46: 46514 | BD46: Y | BE46: 46723 | BF46: 46563 | BG46: 46769
B47: HEARFIELD, Bradd | C47: GPH | D47: h84290H | L47: 46693 | P47: 47182 | U47: 46830 | V47: 46072 | W47: 45707 | X47: Y | Z47: 47574 | AB47: Y | AE47: 46729 | AM47: 46729 | AN47: 46729 | AQ47: 47199 | AR47: N | AS47: 47246 | AU47: N | AV47: Y | AW47: 46460 | AX47: 46806 | AY47: 46852 | AZ47: 47246 | BA47: 46515 | BB47: 47316 | BC47: 46806 | BD47: Y | BE47: 46729 | BF47: 46783 | BG47: 46418
...

Sheet Template
A2: Partnership | C2: < Start Here
A3: Crew Change
A4: Crew Change From
A5: Crew Change To
G10: Legend:
G11: M | H11: Mandatory
G12: Mˣ | H12: Mandatory if applicable — see notes below
G13: R | H13: Recommended
H14: Not Required
A16: Position Reference | B16: Name | C16: Position | D16: Shift | E16: Sam # | F16: From Date | G16: To Date | H16: Comments | I16: 1. Qualification | AC16: 2. Vessel Specific | AG16: 3. Project Specific | AI16: 4. Master Specific | AP16: 5. Cargo System | AT16: 6. High Risk Work Licence (HRWL) | AV16: 7. Permit to Work | AY16: 8. Vessel Induction | BA16: 9. Project Induction
I17: QL-01 | J17: QL-02 | K17: QL-03 | L17: QL-04 | M17: QL-05 | N17: QL-06 | O17: QL-07 | P17: QL-08 | Q17: QL-09 | R17: QL-10 | S17: QL-11 | T17: QL-12 | U17: QL-13 | V17: QL-14 | W17: QL-15 | X17: QL-16 | Y17: QL-17 | Z17: QL-18 | AA17: QL-19 | AB17: QL-20 | AC17: VS-01 | AD17: VS-02 | AE17: VS-04 | AF17: VS-05 | AG17: PS-01 | AH17: PS-02 | AI17: MS-01 | AJ17: MS-02 | AK17: MS-03 | AL17: MS-04 | AM17: MS-05 | AN17: MS-06 | AO17: MS-07 | AP17: CS-01 | AQ17: CS-02 | AR17: CS-03 | AS17: CS-04 | AT17: HR-01 | AU17: HR-02 | AV17: PT-01 | AW17: PT-02 | AX17: PT-03 | AY17: VI-01 | AZ17: VI-02 | BA17: PI-01 | BB17: PI-02 | BC17: PI-03 | BD17: PI-04 | BE17: PI-05 | BF17: PI-06 | BG17: PI-07 | BH17: PI-08 | BI17: PI-09 | BJ17: PI-10
I18: Master | J18: Chief Mate | K18: Master <100m NC | L18: Master <45m NC | M18: Engineer Class 1, Chief Engineer (Motor) | N18: Engineer Class 2, Second Engineer, Chief Engineer <3000 kW (Motor) | O18: Engineer Class 3 NC | P18: Master <24m NC | Q18: Marine Engine Driver Grade 2 NC | R18: Integrated Rating, Able Seafarer - Deck, Able Seafarer - Engineer (STCW Reg II/5 & III/5) | S18: Marine Cook | T18: Certificate of Safety Training (COST) | U18: ECDIS - STCW Reg II/1 & II/2 | V18: GMDSS - STCW Reg IV/2 | W18: Long Range Operator Certificate of Proficiency (LROCP) | X18: Fast Rescue Craft (FRC) | Y18: AMSA Certificate of Medical Fitness - Form 303 | Z18: Provide First Aid - HLTAID011 | AA18: Adv Resuscitation and Oxygen Therapy - HLTIAD015 | AB18: Use hygienic practices for food safety - SITXFSA005 | AC18: Maritime Security Identification Card | AD18: ECDIS Type Specific - Furuno ECDIS, FMD series | AE18: Helm CONNECT - Crew Basic + Jobs | AF18: MRN - Connecting Tug to Barge Articouple System | AG18: MRN - Marine Fauna Observer | AH18: MinRes - Mooring Operations Awareness - Onslow | AI18: Phase 1 - ASD and ATB Theory & Assessment | AJ18: Phase 2 - Simulator Training & Practical Assessment ASD | AK18: Phase 3 - Simulator Training & Practical Assessment ATB | AL18: Phase 4a - On-Water Training & Practical Assessment ASD | AM18: Phase 4b - On-Water Training & Practical Assessment ATB | AN18: Phase 5 - On-Water Passing in the LNG Swing Basin | AO18: Pilbara Ports Port of Ashburton Pilotage Exemption Certificate | AP18: MRN - EMS Tech Material Handling Systems - Single Point Loading System | AQ18: MRN - EMS Tech Material Handling Systems - Self-Unloading System | AR18: Cargo System - Operator - Practical | AS18: Cargo System - Trainer - Practical | AT18: HRWL - Dogging - Dogging (DG) | AU18: HRWL - Vehicle loading crane (CV) | AV18: MinRes - Lock Holder, Isolation and Tagging | AW18: Enter and Work in Confined Spaces - RIIWHS202E | AX18: Work Safely at Heights - RIIWHS204E | AY18: Onboard induction, familiarisation and training - Tug and Barge | AZ18: MRN - Tug and Barge Induction | BA18: MinRes - Code of Conduct & Business Integrity | BB18: MinRes - Corporate Safety Induction | BC18: MinRes - Hazard Report Card, Take Time & JHA | BD18: MinRes - Manual Handling | BE18: MinRes - Operational Health and Safety Induction | BF18: MinRes - Safe and Respectful Behaviours | BG18: MinRes - Welcome to MinRes | BH18: MinRes - Cybersecurity Awareness Training | BI18: MinRes - Critical Risk Management (CRM) Awareness | BJ18: MinRes - Airborne Contaminant Awareness Training
A19: 1 | C19: Master | D19: Shift 1 | F19: =IF(ISBLANK($B$4), "", $B$7) | G19: =IF(ISBLANK($B$4), "", $B$5) | I19: M | J19: =IFERROR(VLOOKUP($B$19,'CREW EXPIRY DATES'!$B$16:$BG$100,5,FALSE),"") | U19: M | V19: M | X19: M³ | Y19: M | Z19: M | AA19: M⁴ | AC19: M | AD19: M | AE19: M | AF19: M | AG19: M | AH19: M | AI19: M | AJ19: M | AK19: M | AL19: M | AM19: M | AN19: M | AO19: M | AP19: M | AQ19: M | AR19: M | AV19: M | AW19: M | AX19: M | AY19: M | AZ19: M | BA19: M | BB19: M | BC19: M | BD19: M | BE19: M | BF19: M | BG19: M | BH19: M | BI19: M | BJ19: M
A20: 2 | C20: Master | D20: Shift 2 | F20: =IF(ISBLANK($B$4), "", $B$7) | G20: =IF(ISBLANK($B$4), "", $B$5) | I20: M | U20: M | V20: M | X20: M³ | Y20: M | Z20: M | AA20: M⁴ | AC20: M | AD20: M | AE20: M | AF20: M | AG20: M | AH20: M | AI20: M | AJ20: M | AK20: M | AL20: M | AM20: M | AN20: M | AO20: M | AP20: M | AQ20: M | AR20: M | AV20: M | AW20: M | AX20: M | AY20: M | AZ20: M | BA20: M | BB20: M | BC20: M | BD20: M | BE20: M | BF20: M | BG20: M | BH20: M | BI20: M | BJ20: M
A21: 3 | C21: Chief Officer | D21: Shift 1 | F21: =IF(ISBLANK($B$4), "", $B$7) | G21: =IF(ISBLANK($B$4), "", $B$5) | J21: M | U21: M | V21: M | X21: M³ | Y21: M | Z21: M | AA21: M⁴ | AC21: M | AD21: M | AE21: M | AF21: M | AG21: M | AH21: M | AI21: R | AJ21: R | AK21: R | AL21: R | AM21: R | AN21: M | AO21: R | AP21: M | AQ21: M | AR21: M | AS21: M | AT21: R | AU21: M⁶ | AV21: M | AY21: M | AZ21: M | BA21: M | BB21: M | BC21: M | BD21: M | BE21: M | BF21: M | BG21: M | BH21: M | BI21: M | BJ21: M
A22: 4 | C22: Chief Officer | D22: Shift 2 | F22: =IF(ISBLANK($B$4), "", $B$7) | G22: =IF(ISBLANK($B$4), "", $B$5) | K22: M | T22: M | U22: M | V22: M | W22: M | X22: M³ | Y22: M | Z22: M | AA22: M⁴ | AC22: M | AD22: M | AE22: M | AF22: M | AG22: M | AH22: M | AI22: R | AJ22: R | AK22: R | AL22: R | AM22: R | AN22: M | AO22: R | AP22: M | AQ22: M | AR22: M | AS22: M | AT22: R | AU22: M⁶ | AV22: M | AY22: M | AZ22: M | BA22: M | BB22: M | BC22: M | BD22: M | BE22: M | BF22: M | BG22: M | BH22: M | BI22: M | BJ22: M
A23: 5 | C23: Second Mate | D23: Shift 1 | F23: =IF(ISBLANK($B$4), "", $B$7) | G23: =IF(ISBLANK($B$4), "", $B$5) | L23: M | T23: M | U23: M | W23: M | X23: M³ | Y23: M | Z23: M | AA23: M⁴ | AC23: M | AD23: M | AE23: M | AF23: M | AG23: M | AH23: M | AP23: M | AQ23: M | AR23: M | AT23: R | AU23: M⁶ | AV23: M | AY23: M | AZ23: M | BA23: M | BB23: M | BC23: M | BD23: M | BE23: M | BF23: M | BG23: M | BH23: M | BI23: M | BJ23: M
A24: 6 | C24: Second Mate | D24: Shift 2 | F24: =IF(ISBLANK($B$4), "", $B$7) | G24: =IF(ISBLANK($B$4), "", $B$5) | L24: M | T24: M | U24: M | W24: M | X24: M³ | Y24: M | Z24: M | AA24: M⁴ | AC24: M | AD24: M | AE24: M | AF24: M | AG24: M | AH24: M | AP24: M | AQ24: M | AR24: M | AT24: R | AU24: M⁶ | AV24: M | AY24: M | AZ24: M | BA24: M | BB24: M | BC24: M | BD24: M | BE24: M | BF24: M | BG24: M | BH24: M | BI24: M | BJ24: M
A25: 7 | C25: Chief Engineer | D25: Shift 1 | F25: =IF(ISBLANK($B$4), "", $B$7) | G25: =IF(ISBLANK($B$4), "", $B$5) | M25: M | X25: M³ | Y25: M | Z25: M | AA25: M⁴ | AC25: M | AE25: M | AH25: M | AP25: M | AQ25: M | AR25: R | AV25: M | AW25: M | AX25: M | AY25: M | AZ25: M | BA25: M | BB25: M | BC25: M | BD25: M | BE25: M | BF25: M | BG25: M | BH25: M | BI25: M | BJ25: M
A26: 8 | C26: First Engineer | D26: Shift 2 | F26: =IF(ISBLANK($B$4), "", $B$7) | G26: =IF(ISBLANK($B$4), "", $B$5) | N26: M | X26: M³ | Y26: M | Z26: M | AA26: M⁴ | AC26: M | AE26: M | AH26: M | AP26: M | AQ26: M | AR26: R | AV26: M | AW26: M | AX26: M | AY26: M | AZ26: M | BA26: M | BB26: M | BC26: M | BD26: M | BE26: M | BF26: M | BG26: M | BH26: M | BI26: M | BJ26: M
A27: 9 | C27: Assistant Engineer | D27: Shift 1 | F27: =IF(ISBLANK($B$4), "", $B$7) | G27: =IF(ISBLANK($B$4), "", $B$5) | O27: M | T27: M | X27: M³ | Y27: M | Z27: M | AA27: M⁴ | AC27: M | AE27: M | AH27: M | AP27: M | AQ27: M | AT27: M | AU27: M⁶ | AV27: M | AX27: M | AY27: M | AZ27: M | BA27: M | BB27: M | BC27: M | BD27: M | BE27: M | BF27: M | BG27: M | BH27: M | BI27: M | BJ27: M
A28: 10 | C28: Assistant Engineer | D28: Shift 2 | F28: =IF(ISBLANK($B$4), "", $B$7) | G28: =IF(ISBLANK($B$4), "", $B$5) | O28: M | T28: M | X28: M³ | Y28: M | Z28: M | AA28: M⁴ | AC28: M | AE28: M | AH28: M | AP28: M | AQ28: M | AT28: M | AU28: M⁶ | AV28: M | AX28: M | AY28: M | AZ28: M | BA28: M | BB28: M | BC28: M | BD28: M | BE28: M | BF28: M | BG28: M | BH28: M | BI28: M | BJ28: M
A29: 11 | C29: GPH | D29: Shift 1 | F29: =IF(ISBLANK($B$4), "", $B$7) | G29: =IF(ISBLANK($B$4), "", $B$5) | P29: M¹ | Q29: M¹ | R29: M¹ | T29: M² | X29: M³ | Y29: M | Z29: M | AA29: M⁴ | AB29: M⁵ | AC29: M | AE29: M | AH29: M | AP29: M | AQ29: M | AT29: M | AU29: M⁶ | AV29: M | AX29: M⁷ | AY29: M | AZ29: M | BA29: M | BB29: M | BC29: M | BD29: M | BE29: M | BF29: M | BG29: M | BH29: M | BI29: M | BJ29: M
A30: 12 | C30: GPH | D30: Shift 2 | F30: =IF(ISBLANK($B$4), "", $B$7) | G30: =IF(ISBLANK($B$4), "", $B$5) | P30: M¹ | Q30: M¹ | R30: M¹ | T30: M² | X30: M³ | Y30: M | Z30: M | AA30: M⁴ | AB30: M⁵ | AC30: M | AE30: M | AH30: M | AP30: M | AQ30: M | AT30: M | AU30: M⁶ | AV30: M | AX30: M⁷ | AY30: M | AZ30: M | BA30: M | BB30: M | BC30: M | BD30: M | BE30: M | BF30: M | BG30: M | BH30: M | BI30: M | BJ30: M
A31: 13 | C31: GPH | D31: Shift 1 | F31: =IF(ISBLANK($B$4), "", $B$7) | G31: =IF(ISBLANK($B$4), "", $B$5) | P31: M¹ | Q31: M¹ | R31: M¹ | T31: M² | X31: M³ | Y31: M | Z31: M | AA31: M⁴ | AB31: M⁵ | AC31: M | AE31: M | AH31: M | AP31: M | AQ31: M | AT31: M | AU31: M⁶ | AV31: M | AX31: M⁷ | AY31: M | AZ31: M | BA31: M | BB31: M | BC31: M | BD31: M | BE31: M | BF31: M | BG31: M | BH31: M | BI31: M | BJ31: M
A32: 14 | C32: GPH | D32: Shift 2 | F32: =IF(ISBLANK($B$4), "", $B$7) | G32: =IF(ISBLANK($B$4), "", $B$5) | P32: M¹ | Q32: M¹ | R32: M¹ | T32: M² | X32: M³ | Y32: M | Z32: M | AA32: M⁴ | AB32: M⁵ | AC32: M | AE32: M | AH32: M | AP32: M | AQ32: M | AT32: M | AU32: M⁶ | AV32: M | AX32: M⁷ | AY32: M | AZ32: M | BA32: M | BB32: M | BC32: M | BD32: M | BE32: M | BF32: M | BG32: M | BH32: M | BI32: M | BJ32: M
A33: 15 | C33: GPH | D33: Shift 1 | F33: =IF(ISBLANK($B$4), "", $B$7) | G33: =IF(ISBLANK($B$4), "", $B$5) | P33: M¹ | Q33: M¹ | R33: M¹ | T33: M² | X33: M³ | Y33: M | Z33: M | AA33: M⁴ | AB33: M⁵ | AC33: M | AE33: M | AH33: M | AP33: M | AQ33: M | AT33: M | AU33: M⁶ | AV33: M | AX33: M⁷ | AY33: M | AZ33: M | BA33: M | BB33: M | BC33: M | BD33: M | BE33: M | BF33: M | BG33: M | BH33: M | BI33: M | BJ33: M
A34: 16 | C34: GPH | D34: Shift 2 | F34: =IF(ISBLANK($B$4), "", $B$7) | G34: =IF(ISBLANK($B$4), "", $B$5) | P34: M¹ | Q34: M¹ | R34: M¹ | T34: M² | X34: M³ | Y34: M | Z34: M | AA34: M⁴ | AB34: M⁵ | AC34: M | AE34: M | AH34: M | AP34: M | AQ34: M | AT34: M | AU34: M⁶ | AV34: M | AX34: M⁷ | AY34: M | AZ34: M | BA34: M | BB34: M | BC34: M | BD34: M | BE34: M | BF34: M | BG34: M | BH34: M | BI34: M | BJ34: M
A35: 15 | C35: Assistant Engineer | D35: Shift 1 | F35: =IF(ISBLANK($B$4), "", $B$7) | G35: =IF(ISBLANK($B$4), "", $B$5) | O35: M | T35: M | X35: M³ | Y35: M | Z35: M | AA35: M⁴ | AC35: M | AE35: M | AH35: M | AP35: M | AQ35: M | AT35: M | AU35: M⁶ | AV35: M | AX35: M | AY35: M | AZ35: M | BA35: M | BB35: M | BC35: M | BD35: M | BE35: M | BF35: M | BG35: M | BH35: M | BI35: M | BJ35: M
A36: 16 | C36: Assistant Engineer | D36: Shift 2 | F36: =IF(ISBLANK($B$4), "", $B$7) | G36: =IF(ISBLANK($B$4), "", $B$5) | O36: M | T36: M | X36: M³ | Y36: M | Z36: M | AA36: M⁴ | AC36: M | AE36: M | AH36: M | AP36: M | AQ36: M | AT36: M | AU36: M⁶ | AV36: M | AX36: M | AY36: M | AZ36: M | BA36: M | BB36: M | BC36: M | BD36: M | BE36: M | BF36: M | BG36: M | BH36: M | BI36: M | BJ36: M
A37: 17 | C37: Cook | D37: N/A | F37: =IF(ISBLANK($B$4), "", $B$7) | G37: =IF(ISBLANK($B$4), "", $B$5) | S37: M | T37: M | X37: M³ | Y37: M | Z37: M | AA37: M⁴ | AC37: M | AV37: M | AY37: M | AZ37: M | BA37: M | BB37: M | BC37: M | BD37: M | BE37: M | BF37: M | BG37: M | BH37: M | BI37: M | BJ37: M

Sheet Template - Matrix
A2: Crew Joining Matrix
A5: Partnership | B5: United Marine Pty Ltd | C5: < Start Here
A6: Crew Change | B6: {=IF(B7="","", INDEX(Lookup!$M$2:$M$135, MATCH(1, (B7 >= Lookup!$O$2:$O$135) * (B7 <= Lookup!$P$2:$P$135) * ($B5 = Lookup!$N$2:$N$135), 0) ) )} | I6: Legend
A7: Crew Change From | D7: Requirements to be confirmed in updated matrix | I7: M | J7: Mandatory Requirement | M7: COMPETENT DDMMYY
A8: Crew Change To | B8: {=IF(ISBLANK(B7), "", INDEX(Lookup!P:P, MATCH(1, (Lookup!N:N=B5) * (Lookup!M:M=B6), 0)))} | I8: R | J8: Recommended Requirement
I9: Marine Order 71 – Certificate of Competency Master | J9: Marine Order 71 – Certificate of Competency Chief Mate | K9: Marine Order 505 – Certificate of Competency Master <100m Near Coastal (NC) | L9: Marine Order 505 – Certificate of Competency Master <45m Near Coastal (NC) | M9: Marine Order 72 – Certificate of Competency Engineer Class 1 | N9: Marine Order 72 – Certificate of Competency Engineer Class 2 | O9: Marine Order 505 – Certificate of Competency Engineer Class 3 Near Coastal (NC) | P9: Marine Order 505 – Certificate of Competency Master <24m Near Coastal (NC) | Q9: Marine Order 505 – Certificate of Competency Marine Engine Driver Grade 2 Near Coastal (NC) | S9: Marine Order 70 – Certificate of Proficiency Marine Cook | T9: Certificate of safety training (full course)—STCW Reg VI/1 | U9: ECDIS—STCW Reg II/1 & II/2 | V9: ECDIS Type Specific - Furuno ECDIS, FMD series | W9: GMDSS—STCW Reg IV/2 | X9: Proficiency in fast rescue boats—STCW Regulation VI/2 Code A -VI/2 table A-VI/2-2 | Y9: Marine Order 76 - Certificate of Medical Fitness (AMSA 303/ AMSA 1850?) | Z9: HLTAID011 Provide first aid | AA9: HLTAID015 Provide advanced resuscitation and oxygen therapy | AB9: SITXFSA005 Use hygienic practices for food safety | AC9: Maritime Security Identification Card | AD9: Theory and user training in DUKC® Series 5 | AE9: Helm Crew - Basic & Crew Jobs | AF9: MRN - Connecting Tug to Barge Articouple System | AG9: MinRes - Mooring Operations Awareness - Onslow | AH9: Phase 1a: ASD and ATB Theory Training/ MRN - Effective Use of Tugs for Pilot Exempt Masters | AI9: Phase 1b: Pilbara Ports Authority (Port of Ashburton) Pilot Exemption Certificate/ MRN - Effective Use of Tugs for Pilot Exempt Masters | AJ9: Phase 2: ASD Tug Handling | AK9: Phase 3: Articulated Tug and Barge (ATB) Manoeuvring & PEC | AL9: Phase 4: ASD/ATB MANOEUVRING, PORT OPERATIONS AND PEC TRAINING | AM9: Phase 5a: Channel Passing | AN9: Phase 5b: Channel Passing | AO9: Pilbara Ports Port of Ashburton Pilotage Exemption Certificate | AP9: ATB EMS Tech Cargo System Competence Assessment | AQ9: MRN - EMS Tech Material Handling Systems - Single Point Loading System | AR9: MRN - EMS Tech Material Handling Systems - Self-Unloading System | AS9: VOC Loading and discharging equipment | AU9: High Risk Work License - Dogging (DG) | AV9: High Risk Work License - Vehicle loading crane (CV) | AX9: RIIWHS202E Enter and Work in Confined Spaces | AY9: RIIWHS204E Work Safely at Heights | AZ9: Onboard induction, familiarisation and training | BA9: MRN - Tug and Barge Induction | BB9: MRN - Marine Contractor Health and Safety | BC9: MinRes - Operational Health and Safety Induction | BD9: MinRes - Safe and Respectful Behaviours | BE9: MinRes - Welcome to MinRes | BF9: MinRes - Code of Conduct & Business Integrity | BG9: MinRes - Corporate Safety Induction | BH9: MinRes - Hazard Report Card, Take Time & JHA | BI9: MinRes - Manual Handling | BJ9: MinRes - Critical Risk Management (CRM) Awareness | BK9: MinRes - Airborne Contaminant Awareness Training | BM9: MRN - Marine Fauna Observer
